try {
  throw "exception"
} finally {
  2 + 2
}
